<?xml version="1.0" ?>
<robot name="partnet_ccf930a5753a7e11f7a4d2929e8727e6">
	<link name="base"/>
	<link name="link_0">
		<visual name="leg-1">
			<origin xyz="0.6433655228052175 -0.17150742041938383 -0.11928940806476107"/>
			<geometry>
				<mesh filename="textured_objs/original-5.obj" scale="0.3 0.3 0.3"/>
			</geometry>
		</visual>
		<collision>
			<origin xyz="0.6433655228052175 -0.17150742041938383 -0.11928940806476107"/>
			<geometry>
				<mesh filename="textured_objs/original-5.obj" scale="0.3 0.3 0.3"/>
			</geometry>
		</collision>
	</link>
	<joint name="joint_0" type="revolute">
		<origin xyz="-0.6433655228052175 0.17150742041938383 0.11928940806476107"/>
		<axis xyz="0 -1 0"/>
		<child link="link_0"/>
		<parent link="link_2"/>
		<limit lower="-0.0" upper="1.1184069846779672"/>
	</joint>
	<link name="link_1">
		<visual name="leg-2">
			<origin xyz="-0.6323725572479443 -0.17508172326538185 -0.12999168228739114"/>
			<geometry>
				<mesh filename="textured_objs/original-4.obj" scale="0.3 0.3 0.3"/>
			</geometry>
		</visual>
		<collision>
			<origin xyz="-0.6323725572479443 -0.17508172326538185 -0.12999168228739114"/>
			<geometry>
				<mesh filename="textured_objs/original-4.obj" scale="0.3 0.3 0.3"/>
			</geometry>
		</collision>
	</link>
	<joint name="joint_1" type="revolute">
		<origin xyz="0.6323725572479443 0.17508172326538185 0.12999168228739114"/>
		<axis xyz="0 1 0"/>
		<child link="link_1"/>
		<parent link="link_2"/>
		<limit lower="0.0" upper="1.2000883936713012"/>
	</joint>
	<link name="link_2">
		<visual name="base_body-3">
			<origin xyz="0 0 0"/>
			<geometry>
				<mesh filename="textured_objs/original-3.obj" scale="0.3 0.3 0.3"/>
			</geometry>
		</visual>
		<visual name="base_body-3">
			<origin xyz="0 0 0"/>
			<geometry>
				<mesh filename="textured_objs/original-2.obj" scale="0.3 0.3 0.3"/>
			</geometry>
		</visual>
		<visual name="base_body-3">
			<origin xyz="0 0 0"/>
			<geometry>
				<mesh filename="textured_objs/original-1.obj" scale="0.3 0.3 0.3"/>
			</geometry>
		</visual>
		<collision>
			<origin xyz="0 0 0"/>
			<geometry>
				<mesh filename="textured_objs/original-3.obj" scale="0.3 0.3 0.3"/>
			</geometry>
		</collision>
		<collision>
			<origin xyz="0 0 0"/>
			<geometry>
				<mesh filename="textured_objs/original-2.obj" scale="0.3 0.3 0.3"/>
			</geometry>
		</collision>
		<collision>
			<origin xyz="0 0 0"/>
			<geometry>
				<mesh filename="textured_objs/original-1.obj" scale="0.3 0.3 0.3"/>
			</geometry>
		</collision>
	</link>
	<joint name="joint_2" type="fixed">
		<origin rpy="1.570796326794897 0 -1.570796326794897" xyz="0 0 0"/>
		<child link="link_2"/>
		<parent link="base"/>
	</joint>
</robot>
