<?xml version="1.0" ?>
<robot name="partnet_9197731b76f4a5311c4715249ed9b23b">
	<link name="base"/>
	<link name="link_0">
		<visual name="leg-1">
			<origin xyz="0.6158811496506598 -0.09728600000000043 -0.08004448252724705"/>
			<geometry>
				<mesh filename="textured_objs/original-3.obj" scale="0.3 0.3 0.3"/>
			</geometry>
		</visual>
		<collision>
			<origin xyz="0.6158811496506598 -0.09728600000000043 -0.08004448252724705"/>
			<geometry>
				<mesh filename="textured_objs/original-3.obj" scale="0.3 0.3 0.3"/>
			</geometry>
		</collision>
	</link>
	<joint name="joint_0" type="revolute">
		<origin xyz="-0.6158811496506598 0.09728600000000043 0.08004448252724705"/>
		<axis xyz="0 -1 0"/>
		<child link="link_0"/>
		<parent link="link_2"/>
		<limit lower="-0.0" upper="1.2000883936713007"/>
	</joint>
	<link name="link_1">
		<visual name="leg-2">
			<origin xyz="-0.5912784925662327 -0.09728599999999954 -0.08022447130102006"/>
			<geometry>
				<mesh filename="textured_objs/original-9.obj" scale="0.3 0.3 0.3"/>
			</geometry>
		</visual>
		<collision>
			<origin xyz="-0.5912784925662327 -0.09728599999999954 -0.08022447130102006"/>
			<geometry>
				<mesh filename="textured_objs/original-9.obj" scale="0.3 0.3 0.3"/>
			</geometry>
		</collision>
	</link>
	<joint name="joint_1" type="revolute">
		<origin xyz="0.5912784925662327 0.09728599999999954 0.08022447130102006"/>
		<axis xyz="0 1 0"/>
		<child link="link_1"/>
		<parent link="link_2"/>
		<limit lower="0.0" upper="1.319468914507713"/>
	</joint>
	<link name="link_2">
		<visual name="base_body-3">
			<origin xyz="0 0 0"/>
			<geometry>
				<mesh filename="textured_objs/original-2.obj" scale="0.3 0.3 0.3"/>
			</geometry>
		</visual>
		<visual name="base_body-3">
			<origin xyz="0 0 0"/>
			<geometry>
				<mesh filename="textured_objs/original-8.obj" scale="0.3 0.3 0.3"/>
			</geometry>
		</visual>
		<visual name="base_body-3">
			<origin xyz="0 0 0"/>
			<geometry>
				<mesh filename="textured_objs/original-5.obj" scale="0.3 0.3 0.3"/>
			</geometry>
		</visual>
		<visual name="base_body-3">
			<origin xyz="0 0 0"/>
			<geometry>
				<mesh filename="textured_objs/original-6.obj" scale="0.3 0.3 0.3"/>
			</geometry>
		</visual>
		<visual name="base_body-3">
			<origin xyz="0 0 0"/>
			<geometry>
				<mesh filename="textured_objs/original-11.obj" scale="0.3 0.3 0.3"/>
			</geometry>
		</visual>
		<visual name="base_body-3">
			<origin xyz="0 0 0"/>
			<geometry>
				<mesh filename="textured_objs/original-12.obj" scale="0.3 0.3 0.3"/>
			</geometry>
		</visual>
		<collision>
			<origin xyz="0 0 0"/>
			<geometry>
				<mesh filename="textured_objs/original-2.obj" scale="0.3 0.3 0.3"/>
			</geometry>
		</collision>
		<collision>
			<origin xyz="0 0 0"/>
			<geometry>
				<mesh filename="textured_objs/original-8.obj" scale="0.3 0.3 0.3"/>
			</geometry>
		</collision>
		<collision>
			<origin xyz="0 0 0"/>
			<geometry>
				<mesh filename="textured_objs/original-5.obj" scale="0.3 0.3 0.3"/>
			</geometry>
		</collision>
		<collision>
			<origin xyz="0 0 0"/>
			<geometry>
				<mesh filename="textured_objs/original-6.obj" scale="0.3 0.3 0.3"/>
			</geometry>
		</collision>
		<collision>
			<origin xyz="0 0 0"/>
			<geometry>
				<mesh filename="textured_objs/original-11.obj" scale="0.3 0.3 0.3"/>
			</geometry>
		</collision>
		<collision>
			<origin xyz="0 0 0"/>
			<geometry>
				<mesh filename="textured_objs/original-12.obj" scale="0.3 0.3 0.3"/>
			</geometry>
		</collision>
	</link>
	<joint name="joint_2" type="fixed">
		<origin rpy="1.570796326794897 0 -1.570796326794897" xyz="0 0 0"/>
		<child link="link_2"/>
		<parent link="base"/>
	</joint>
</robot>
